[2024-08-27T01:19:40.267+0000] {local_task_job_runner.py:120} INFO - ::group::Pre task execution logs
[2024-08-27T01:19:40.709+0000] {taskinstance.py:2076} INFO - Dependencies all met for dep_context=non-requeueable deps ti=<TaskInstance: postgres_operator_dag.create_table scheduled__2024-06-26T00:00:00+00:00 [queued]>
[2024-08-27T01:19:40.835+0000] {taskinstance.py:2076} INFO - Dependencies all met for dep_context=requeueable deps ti=<TaskInstance: postgres_operator_dag.create_table scheduled__2024-06-26T00:00:00+00:00 [queued]>
[2024-08-27T01:19:40.835+0000] {taskinstance.py:2306} INFO - Starting attempt 1 of 4
[2024-08-27T01:19:41.220+0000] {taskinstance.py:2330} INFO - Executing <Task(SQLExecuteQueryOperator): create_table> on 2024-06-26 00:00:00+00:00
[2024-08-27T01:19:41.307+0000] {standard_task_runner.py:90} INFO - Running: ['***', 'tasks', 'run', 'postgres_operator_dag', 'create_table', 'scheduled__2024-06-26T00:00:00+00:00', '--job-id', '145', '--raw', '--subdir', 'DAGS_FOLDER/dag_creation.py', '--cfg-path', '/tmp/tmpfs0w8e7a']
[2024-08-27T01:19:41.308+0000] {standard_task_runner.py:91} INFO - Job 145: Subtask create_table
[2024-08-27T01:19:41.301+0000] {warnings.py:112} WARNING - /home/***/.local/lib/python3.12/site-packages/***/task/task_runner/standard_task_runner.py:61: DeprecationWarning: This process (pid=412) is multi-threaded, use of fork() may lead to deadlocks in the child.
  pid = os.fork()

[2024-08-27T01:19:41.358+0000] {standard_task_runner.py:63} INFO - Started process 435 to run task
[2024-08-27T01:19:42.085+0000] {task_command.py:426} INFO - Running <TaskInstance: postgres_operator_dag.create_table scheduled__2024-06-26T00:00:00+00:00 [running]> on host 6a900cf20cab
[2024-08-27T01:19:43.380+0000] {taskinstance.py:2648} INFO - Exporting env vars: AIRFLOW_CTX_DAG_OWNER='anderson_oca' AIRFLOW_CTX_DAG_ID='postgres_operator_dag' AIRFLOW_CTX_TASK_ID='create_table' AIRFLOW_CTX_EXECUTION_DATE='2024-06-26T00:00:00+00:00' AIRFLOW_CTX_TRY_NUMBER='1' AIRFLOW_CTX_DAG_RUN_ID='scheduled__2024-06-26T00:00:00+00:00'
[2024-08-27T01:19:43.394+0000] {taskinstance.py:430} INFO - ::endgroup::
[2024-08-27T01:19:43.752+0000] {sql.py:276} INFO - Executing: 
            CREATE TABLE IF NOT EXISTS fin_mundo (
            dt DATE,
            pais VARCHAR(30)
            );
          
[2024-08-27T01:19:43.874+0000] {taskinstance.py:441} INFO - ::group::Post task execution logs
[2024-08-27T01:19:43.999+0000] {taskinstance.py:2905} ERROR - Task failed with exception
Traceback (most recent call last):
  File "/home/airflow/.local/lib/python3.12/site-packages/airflow/models/taskinstance.py", line 465, in _execute_task
    result = _execute_callable(context=context, **execute_callable_kwargs)
             ^^^^^^^^^^^^^^^^^^^^^^^^^^^^^^^^^^^^^^^^^^^^^^^^^^^^^^^^^^^^^
  File "/home/airflow/.local/lib/python3.12/site-packages/airflow/models/taskinstance.py", line 432, in _execute_callable
    return execute_callable(context=context, **execute_callable_kwargs)
           ^^^^^^^^^^^^^^^^^^^^^^^^^^^^^^^^^^^^^^^^^^^^^^^^^^^^^^^^^^^^
  File "/home/airflow/.local/lib/python3.12/site-packages/airflow/models/baseoperator.py", line 401, in wrapper
    return func(self, *args, **kwargs)
           ^^^^^^^^^^^^^^^^^^^^^^^^^^^
  File "/home/airflow/.local/lib/python3.12/site-packages/airflow/providers/common/sql/operators/sql.py", line 277, in execute
    hook = self.get_db_hook()
           ^^^^^^^^^^^^^^^^^^
  File "/home/airflow/.local/lib/python3.12/site-packages/airflow/providers/common/sql/operators/sql.py", line 188, in get_db_hook
    return self._hook
           ^^^^^^^^^^
  File "/usr/local/lib/python3.12/functools.py", line 995, in __get__
    val = self.func(instance)
          ^^^^^^^^^^^^^^^^^^^
  File "/home/airflow/.local/lib/python3.12/site-packages/airflow/providers/common/sql/operators/sql.py", line 150, in _hook
    conn = BaseHook.get_connection(conn_id)
           ^^^^^^^^^^^^^^^^^^^^^^^^^^^^^^^^
  File "/home/airflow/.local/lib/python3.12/site-packages/airflow/hooks/base.py", line 83, in get_connection
    conn = Connection.get_connection_from_secrets(conn_id)
           ^^^^^^^^^^^^^^^^^^^^^^^^^^^^^^^^^^^^^^^^^^^^^^^
  File "/home/airflow/.local/lib/python3.12/site-packages/airflow/models/connection.py", line 519, in get_connection_from_secrets
    raise AirflowNotFoundException(f"The conn_id `{conn_id}` isn't defined")
airflow.exceptions.AirflowNotFoundException: The conn_id `postgres_operator_dag` isn't defined
[2024-08-27T01:19:44.074+0000] {taskinstance.py:1206} INFO - Marking task as UP_FOR_RETRY. dag_id=postgres_operator_dag, task_id=create_table, run_id=scheduled__2024-06-26T00:00:00+00:00, execution_date=20240626T000000, start_date=20240827T011940, end_date=20240827T011944
[2024-08-27T01:19:44.205+0000] {standard_task_runner.py:110} ERROR - Failed to execute job 145 for task create_table (The conn_id `postgres_operator_dag` isn't defined; 435)
[2024-08-27T01:19:44.352+0000] {local_task_job_runner.py:240} INFO - Task exited with return code 1
[2024-08-27T01:19:44.506+0000] {taskinstance.py:3503} INFO - 0 downstream tasks scheduled from follow-on schedule check
[2024-08-27T01:19:44.518+0000] {local_task_job_runner.py:222} INFO - ::endgroup::
